<?xml version='1.0'?>
<sdf version="1.6">
    <model name="sim_scout">
        <static>false</static>
        <link name="base">
            <pose>0 0 0 0 0 0</pose>
            <inertial>
                <mass>5.119</mass>
                <inertia>
                    <ixx>0.0849</ixx>
                    <ixy>0.0</ixy> 
                    <ixz>0.0</ixz> 
                    <iyy>0.1078</iyy>     
                    <iyz>0.0</iyz>      
                    <izz>0.0475</izz>      
                </inertia>
            </inertial>
 
            <collision name="collision">
                <geometry>
                    <mesh>
                        <uri>model://scout/meshes/scout_base_collision.stl</uri>
                        <scale>0.001 0.001 0.001</scale>
                    </mesh>
                    
                </geometry>
                <surface>
            <friction>
              <ode>
                <mu>.7</mu>
                <mu2>.7</mu2>
                <slip1>0.5</slip1>
                <slip2>0.5</slip2>
              </ode>
            </friction>
          </surface>
            </collision>
            <visual name="visual">

                <geometry>
                    <mesh>
                        <uri>model://scout/meshes/scout_base.stl</uri>
                        <scale>0.001 0.001 0.001</scale>
                    </mesh>
                </geometry>
            </visual>

        </link>

        
        
        <!-- DRIVETRAIN -->
        <include>
            <uri>model://mid_wheel</uri>
            <name>midleft_wheel</name>
            <pose>0.0 0.176911 0.031115 0 1.5707 1.5707</pose>
        </include>
        <include>
            <uri>model://mid_wheel</uri>
            <name>midright_wheel</name>
            <pose>0.0 -0.176911 0.031115 0 1.5707 1.5707</pose>
        </include>
        <include>
            <uri>model://large_wheel</uri>
            <name>frontleft_wheel</name>
            <pose>0.1143 0.176911 0.079502 0 1.5707 1.5707</pose>
        </include>
        <include>
            <uri>model://large_wheel</uri>
            <name>frontright_wheel</name>
            <pose>0.1143 -0.176911 0.079502 0 1.5707 1.5707</pose>
        </include>
        <include>
            <uri>model://large_wheel</uri>
            <name>backleft_wheel</name>
            <pose>-0.1143 0.176911 0.079502 0 1.5707 1.5707</pose>
        </include>
        <include>
            <uri>model://large_wheel</uri>
            <name>backright_wheel</name>
            <pose>-0.1143 -0.176911 0.079502 0 1.5707 1.5707</pose>
        </include>
        <joint type="revolute" name="drivetrain_frontleft_wheel_joint">
            <pose frame=''>0 0 0 0 0 0</pose>
            <child>frontleft_wheel::large_wheel</child>
            <parent>base</parent>
            <axis>
                <xyz>0 0 1</xyz>
                <dynamics>
                    <friction>0.2</friction>
                </dynamics>
            </axis>
            <physics>
                <ode>
                    <limit>
                        <cfm>0</cfm>
                        <erp>0.2</erp>
                    </limit>
                    <suspension>
                        <cfm>0</cfm>
                        <erp>0.2</erp>
                    </suspension>
                </ode>
            </physics>
        </joint>
        <joint type="revolute" name="drivetrain_frontright_wheel_joint">
            <pose frame=''>0 0 0 0 0 0</pose>
            <child>frontright_wheel::large_wheel</child>
            <parent>base</parent>
            <axis>
                <xyz>0 0 1</xyz>
                <dynamics>
                    <friction>0.2</friction>
                </dynamics>
            </axis>
            <physics>
                <ode>
                    <limit>
                        <cfm>0</cfm>
                        <erp>0.2</erp>
                    </limit>
                    <suspension>
                        <cfm>0</cfm>
                        <erp>0.2</erp>
                    </suspension>
                </ode>
            </physics>
        </joint>
        <joint type="revolute" name="drivetrain_backleft_wheel_joint">
            <pose frame=''>0 0 0 0 0 0</pose>
            <child>backleft_wheel::large_wheel</child>
            <parent>base</parent>
            <axis>
                <xyz>0 0 1</xyz>
                <dynamics>
                    <friction>0.2</friction>
                </dynamics>
            </axis>
            <physics>
                <ode>
                    <limit>
                        <cfm>0</cfm>
                        <erp>0.2</erp>
                    </limit>
                    <suspension>
                        <cfm>0</cfm>
                        <erp>0.2</erp>
                    </suspension>
                </ode>
            </physics>
        </joint>
        <joint type="revolute" name="drivetrain_backright_wheel_joint">
            <pose frame=''>0 0 0 0 0 0</pose>
            <child>backright_wheel::large_wheel</child>
            <parent>base</parent>
            <axis>
                <xyz>0 0 1</xyz>
                <dynamics>
                    <friction>0.2</friction>
                </dynamics>
            </axis>
            <physics>
                <ode>
                    <limit>
                        <cfm>0</cfm>
                        <erp>0.2</erp>
                    </limit>
                    <suspension>
                        <cfm>0</cfm>
                        <erp>0.2</erp>
                    </suspension>
                </ode>
            </physics>
        </joint>
        
        <joint type="revolute" name="drivetrain_midleft_wheel_joint">
            <child>midleft_wheel::mid_wheel</child>
            <parent>base</parent>
            <axis>
                <xyz>0 0 1</xyz>
                <dynamics>
                    <friction>0.2</friction>
                </dynamics>
            </axis>
            <physics>
                <ode>
                    <limit>
                        <cfm>0</cfm>
                        <erp>0.2</erp>
                    </limit>
                    <suspension>
                        <cfm>0</cfm>
                        <erp>0.2</erp>
                    </suspension>
                </ode>
            </physics>
        </joint> 
        
        <joint type="revolute" name="drivetrain_midright_wheel_joint">
            <child>midright_wheel::mid_wheel</child>
            <parent>base</parent>
            <axis>
                <xyz>0 0 1</xyz>
                <dynamics>
                    <friction>0.2</friction>
                </dynamics>
            </axis>
            <physics>
                <ode>
                    <limit>
                        <cfm>0</cfm>
                        <erp>0.2</erp>
                    </limit>
                    <suspension>
                        <cfm>0</cfm>
                        <erp>0.2</erp>
                    </suspension>
                </ode>
            </physics>
        </joint> 

        <!-- BOOM -->
        <!-- DISABLED FOR NOW UNTIL CONTROLLER IS BUILT 
        <link name="boom">
            <pose>0.186944 0 0.1221232 1.570796327 0 1.570796327</pose>
            <inertial>
                <pose>0 -0.0049022 0.0502158 0 0 0</pose>
                <mass>0.063049339</mass>
                <inertia>
                    <ixx>0.000184004</ixx>
                    <ixy>0.0</ixy> 
                    <ixz>0.0</ixz> 
                    <iyy>0.000221215</iyy>     
                    <iyz>0.0</iyz>      
                    <izz>0.0000506</izz>      
                </inertia>
            </inertial>
            <collision name="collision">
                <geometry>
                    <mesh>
                        <uri>model://scout/meshes/365001.stl</uri>
                    <scale>0.001 0.001 0.001</scale>
                </mesh>
                </geometry>
                <surface>
                    <friction>
                      <ode>
                        <mu>.7</mu>
                        <mu2>.7</mu2>
                        <slip1>0.5</slip1>
                        <slip2>0.5</slip2>
                        <fdir1>0 1 0</fdir1>
                      </ode>
                    </friction>
                </surface>
            </collision>
            <visual name="visual">
            <geometry>
                <mesh>
                    <uri>model://scout/meshes/365001.stl</uri>
                    <scale>0.001 0.001 0.001</scale>
                </mesh>
            </geometry>
            </visual>
        </link>
        <link name="bucket">
            <pose>0.359918 0 0.0809752 1.570796327 0 1.570796327</pose>
            <inertial>
                <pose>0 0.0143256 0.0276606 0 0 0</pose>
                <mass>0.07847148</mass>
                <inertia>
                    <ixx>0.0000586</ixx>
                    <ixy>0.0</ixy> 
                    <ixz>0.0</ixz> 
                    <iyy>0.0002736</iyy>     
                    <iyz>0.0</iyz>      
                    <izz>0.000293</izz>      
                </inertia>
            </inertial>
            <collision name="collision">
                <geometry>
                    <mesh>
                        <uri>model://scout/meshes/365000.stl</uri>
                    <scale>0.001 0.001 0.001</scale>
                </mesh>
                </geometry>
                <surface>
                    <friction>
                      <ode>
                        <mu>.7</mu>
                        <mu2>.7</mu2>
                        <slip1>0.5</slip1>
                        <slip2>0.5</slip2>
                        <fdir1>0 1 0</fdir1>
                      </ode>
                    </friction>
                </surface>
            </collision>
            <visual name="visual">
            <geometry>
                <mesh>
                    <uri>model://scout/meshes/365000.stl</uri>
                    <scale>0.001 0.001 0.001</scale>
                </mesh>
            </geometry>
            </visual>
        </link>
        <link name="boomlink">
            <pose>0.359918 0 0.1142492 1.343903716  0 1.570796327</pose>
            <inertial>
                <pose>0 0.0176 -0.0783844 0 0 0</pose>
                <mass>0.082100219</mass>
                <inertia>
                    <ixx>0.000208</ixx>
                    <ixy>0.0</ixy> 
                    <ixz>0.0</ixz> 
                    <iyy>0.000205</iyy>     
                    <iyz>0.0</iyz>      
                    <izz>0.0000134</izz>      
                </inertia>
            </inertial>
            <collision name="collision">
                <geometry>
                    <mesh>
                        <uri>model://scout/meshes/365003.stl</uri>
                    <scale>0.001 0.001 0.001</scale>
                </mesh>
                </geometry>
                <surface>
                    <friction>
                      <ode>
                        <mu>.7</mu>
                        <mu2>.7</mu2>
                        <slip1>0.5</slip1>
                        <slip2>0.5</slip2>
                        <fdir1>0 1 0</fdir1>
                      </ode>
                    </friction>
                </surface>
            </collision>
            <visual name="visual">
            <geometry>
                <mesh>
                    <uri>model://scout/meshes/365003.stl</uri>
                    <scale>0.001 0.001 0.001</scale>
                </mesh>
            </geometry>
            </visual>
        </link>
        <link name="rocker">
            <pose>0.206756 0 0.0802132 1.134463056  0 1.570796327</pose>
            <inertial>
                <pose>0 0.0176 -0.0783844 0 0 0</pose>
                <mass>0.082100219</mass>
                <inertia>
                    <ixx>0.000208</ixx>
                    <ixy>0.0</ixy> 
                    <ixz>0.0</ixz> 
                    <iyy>0.000205</iyy>     
                    <iyz>0.0</iyz>      
                    <izz>0.0000134</izz>      
                </inertia>
            </inertial>
            <collision name="collision">
                <geometry>
                    <mesh>
                        <uri>model://scout/meshes/365004.stl</uri>
                    <scale>0.001 0.001 0.001</scale>
                </mesh>
                </geometry>
                <surface>
                    <friction>
                      <ode>
                        <mu>.7</mu>
                        <mu2>.7</mu2>
                        <slip1>0.5</slip1>
                        <slip2>0.5</slip2>
                        <fdir1>0 1 0</fdir1>
                      </ode>
                    </friction>
                </surface>
            </collision>
            <visual name="visual">
            <geometry>
                <mesh>
                    <uri>model://scout/meshes/365004.stl</uri>
                    <scale>0.001 0.001 0.001</scale>
                </mesh>
            </geometry>
            </visual>
        </link>
         <joint type="revolute" name="boom_base_joint">
            <child>boom</child>
            <parent>base</parent>
            <axis>
                <xyz>1 0 0</xyz>
                <dynamics>
                    <damping>0</damping>
                </dynamics>
            </axis>
            <physics>
                <ode>
                    <limit>
                        <cfm>0</cfm>
                        <erp>0.2</erp>
                    </limit>
                    <suspension>
                        <cfm>0</cfm>
                        <erp>0.2</erp>
                    </suspension>
                </ode>
            </physics>
        </joint> 
        <joint type="revolute" name="bucket_boom_joint">
            <child>bucket</child>
            <parent>boom</parent>
            <axis>
                <xyz>1 0 0</xyz>
                <dynamics>
                    <damping>0</damping>
                </dynamics>
            </axis>
            <physics>
                <ode>
                    <limit>
                        <cfm>0</cfm>
                        <erp>0.2</erp>
                    </limit>
                    <suspension>
                        <cfm>0</cfm>
                        <erp>0.2</erp>
                    </suspension>
                </ode>
            </physics>
        </joint> 
        <joint type="revolute" name="boomlink_bucket_joint">
            <child>boomlink</child>
            <parent>bucket</parent>
            <axis>
                <xyz>1 0 0</xyz>
                <dynamics>
                    <damping>0</damping>
                </dynamics>
            </axis>
            <physics>
                <ode>
                    <limit>
                        <cfm>0</cfm>
                        <erp>0.2</erp>
                    </limit>
                    <suspension>
                        <cfm>0</cfm>
                        <erp>0.2</erp>
                    </suspension>
                </ode>
            </physics>
        </joint>
        <joint type="revolute" name="rocker_boomlink_joint">
            <child>rocker</child>
            <parent>boomlink</parent>
            <axis>
                <xyz>1 0 0</xyz>
                <dynamics>
                    <damping>0</damping>
                </dynamics>
            </axis>
            <physics>
                <ode>
                    <limit>
                        <cfm>0</cfm>
                        <erp>0.2</erp>
                    </limit>
                    <suspension>
                        <cfm>0</cfm>
                        <erp>0.2</erp>
                    </suspension>
                </ode>
            </physics>
        </joint> 
        <joint type="revolute" name="rocker_boom_joint">
            <pose frame=''>0 0.04191 0  0 0 0</pose>
            <child>rocker</child>
            <parent>boom</parent>
            <axis>
                <xyz>1 0 0</xyz>
                <dynamics>
                    <damping>0</damping>
                </dynamics>
            </axis>
            <physics>
                <ode>
                    <limit>
                        <cfm>0</cfm>
                        <erp>0.2</erp>
                    </limit>
                    <suspension>
                        <cfm>0</cfm>
                        <erp>0.2</erp>
                    </suspension>
                </ode>
            </physics>
        </joint> 
        BOOM DISABLE -->

        <!-- SENSORS -->
        <!-- -->
        <include>
            <uri>model://110015-NEXT</uri>
            <pose>-0.043688 0.099314 0.083566 0 0 1.570796327</pose> 
        </include>
        <joint name="base_leftimu" type="fixed">
            <child>110015-NEXT::LeftIMU</child>
            <parent>base</parent>
        </joint>
        <include>
            <uri>model://110015-3551284</uri>
            <pose>0.043688 -0.099314 0.083566 0 0 -1.570796327</pose>
        </include>
        <joint name="base_rightimu" type="fixed">
            <child>110015-3551284::RightIMU</child>
            <parent>base</parent>
        </joint>
         <!-- SONAR SENSORS -->
        
        <include>
            <uri>model://110001-FLSonar</uri>
            <pose>0.22169 0.10960 0.15401 0 -2.0943 0</pose> 
        </include>
        <joint name="base_frontleftsonar" type="fixed">
            <child>110001-FLSonar::FLSonar</child>
            <parent>base</parent>
        </joint>
        <include>
            <uri>model://110001-FRSonar</uri>
            <pose>0.22169 -0.10960 0.15401 0 -2.0943 0</pose> 
        </include>
        <joint name="base_frontrightsonar" type="fixed">
            <child>110001-FRSonar::FRSonar</child>
            <parent>base</parent>
        </joint>
        <include>
            <uri>model://110001-BLSonar</uri>
            <pose>-0.22169 0.10960 0.15401 3.14159 -1.0471 0</pose> 
        </include>
        <joint name="base_backleftsonar" type="fixed">
            <child>110001-BLSonar::BLSonar</child>
            <parent>base</parent>
        </joint>
        <include>
            <uri>model://110001-BRSonar</uri>
            <pose>-0.22169 -0.10960 0.15401 3.14159 -1.0471 0</pose> 
        </include>
        <joint name="base_backrightsonar" type="fixed">
            <child>110001-BRSonar::BRSonar</child>
            <parent>base</parent>
        </joint>
        <!-- -->
        
        
    </model>

</sdf>
